[2025-01-13T09:57:37.142+0000] {taskinstance.py:1956} INFO - Dependencies all met for dep_context=non-requeueable deps ti=<TaskInstance: load_and_merge_data.product_info_data manual__2025-01-13T09:57:35.202119+00:00 [queued]>
[2025-01-13T09:57:37.155+0000] {taskinstance.py:1956} INFO - Dependencies all met for dep_context=requeueable deps ti=<TaskInstance: load_and_merge_data.product_info_data manual__2025-01-13T09:57:35.202119+00:00 [queued]>
[2025-01-13T09:57:37.156+0000] {taskinstance.py:2170} INFO - Starting attempt 1 of 3
[2025-01-13T09:57:37.173+0000] {taskinstance.py:2191} INFO - Executing <Task(PythonOperator): product_info_data> on 2025-01-13 09:57:35.202119+00:00
[2025-01-13T09:57:37.185+0000] {standard_task_runner.py:60} INFO - Started process 4086 to run task
[2025-01-13T09:57:37.189+0000] {standard_task_runner.py:87} INFO - Running: ['***', 'tasks', 'run', 'load_and_merge_data', 'product_info_data', 'manual__2025-01-13T09:57:35.202119+00:00', '--job-id', '2240', '--raw', '--subdir', 'DAGS_FOLDER/load_and_merge_data.py', '--cfg-path', '/tmp/tmpui68r8_5']
[2025-01-13T09:57:37.192+0000] {standard_task_runner.py:88} INFO - Job 2240: Subtask product_info_data
[2025-01-13T09:57:37.530+0000] {task_command.py:423} INFO - Running <TaskInstance: load_and_merge_data.product_info_data manual__2025-01-13T09:57:35.202119+00:00 [running]> on host ead46257444e
[2025-01-13T09:57:37.635+0000] {taskinstance.py:2480} INFO - Exporting env vars: AIRFLOW_CTX_DAG_OWNER='avbershits' AIRFLOW_CTX_DAG_ID='load_and_merge_data' AIRFLOW_CTX_TASK_ID='product_info_data' AIRFLOW_CTX_EXECUTION_DATE='2025-01-13T09:57:35.202119+00:00' AIRFLOW_CTX_TRY_NUMBER='1' AIRFLOW_CTX_DAG_RUN_ID='manual__2025-01-13T09:57:35.202119+00:00'
[2025-01-13T09:57:37.648+0000] {base.py:83} INFO - Using connection ID 'dwh_db' for task execution.
[2025-01-13T09:57:37.674+0000] {taskinstance.py:2698} ERROR - Task failed with exception
Traceback (most recent call last):
  File "/home/airflow/.local/lib/python3.8/site-packages/airflow/models/taskinstance.py", line 433, in _execute_task
    result = execute_callable(context=context, **execute_callable_kwargs)
  File "/home/airflow/.local/lib/python3.8/site-packages/airflow/operators/python.py", line 199, in execute
    return_value = self.execute_callable()
  File "/home/airflow/.local/lib/python3.8/site-packages/airflow/operators/python.py", line 216, in execute_callable
    return self.python_callable(*self.op_args, **self.op_kwargs)
  File "/opt/airflow/dags/load_and_merge_data.py", line 34, in load_and_merge_data
    pk_columns = primary_keys[table_name]                                                   # Подтягиваем наименование столбцов, по которым ищем дубликаты
KeyError: 'product'
[2025-01-13T09:57:37.684+0000] {taskinstance.py:1138} INFO - Marking task as UP_FOR_RETRY. dag_id=load_and_merge_data, task_id=product_info_data, execution_date=20250113T095735, start_date=20250113T095737, end_date=20250113T095737
[2025-01-13T09:57:37.698+0000] {standard_task_runner.py:107} ERROR - Failed to execute job 2240 for task product_info_data ('product'; 4086)
[2025-01-13T09:57:37.737+0000] {local_task_job_runner.py:234} INFO - Task exited with return code 1
[2025-01-13T09:57:38.086+0000] {taskinstance.py:3280} INFO - 0 downstream tasks scheduled from follow-on schedule check
